2018-12-24 15:24:05,867 - ERROR - Sentry responded with an API error: APIError(Invalid api key)
2018-12-24 15:24:05,868 - ERROR - ["InternalError: (pymysql.err.InternalError) (1046, 'No database selected') [SQL: 'SELECT\\n                       record_pk,\\n                       `domain`\\n                       FROM\\n                       bulletin_search_domain_list\\n                       WHERE\\n                           status=0 \\n                       limit 50\\n                       for update'] (Background on this error at: http://sqlalche.me/e/2j85)", '  File "domain_dns/worker.py", line 504, in select_data', '  File "sqlalchemy/orm/session.py", line 1176, in execute', '  File "sqlalchemy/engine/base.py", line 948, in execute', '  File "sqlalchemy/sql/elements.py", line 269, in _execute_on_connection', '  File "sqlalchemy/engine/base.py", line 1060, in _execute_clauseelement', '  File "sqlalchemy/engine/base.py", line 1200, in _execute_context', '  File "sqlalchemy/engine/base.py", line 1413, in _handle_dbapi_exception', '  File "sqlalchemy/util/compat.py", line 265, in raise_from_cause', '  File "sqlalchemy/util/compat.py", line 248, in reraise', '  File "sqlalchemy/engine/base.py", line 1193, in _execute_context', '  File "sqlalchemy/engine/default.py", line 509, in do_execute', '  File "pymysql/cursors.py", line 170, in execute', '  File "pymysql/cursors.py", line 328, in _query', '  File "pymysql/connections.py", line 516, in query', '  File "pymysql/connections.py", line 727, in _read_query_result', '  File "pymysql/connections.py", line 1066, in read', '  File "pymysql/connections.py", line 683, in _read_packet', '  File "pymysql/protocol.py", line 220, in check_error', '  File "pymysql/err.py", line 109, in raise_mysql_exception']
2018-12-24 15:24:09,335 - ERROR - dictionary changed size during iteration
Traceback (most recent call last):
  File "/anaconda3/lib/python3.7/site-packages/raven/utils/serializer/manager.py", line 69, in transform
    return serializer.serialize(value, **kwargs)
  File "/anaconda3/lib/python3.7/site-packages/raven/utils/serializer/base.py", line 120, in serialize
    iteritems(value)))
  File "/anaconda3/lib/python3.7/site-packages/raven/utils/serializer/base.py", line 117, in <genexpr>
    (self.make_key(self.recurse(k, **kwargs)), self.recurse(v, **kwargs))
RuntimeError: dictionary changed size during iteration
2018-12-24 15:24:09,503 - ERROR - Sentry responded with an API error: APIError(Invalid api key)
2018-12-24 15:24:09,503 - ERROR - ['KeyboardInterrupt', '  File "pydev/pydevd.py", line 1591, in <module>', '  File "pydev/pydevd.py", line 1018, in run', '  File "_pydev_imps/_pydev_execfile.py", line 18, in execfile', '  File "domain_dns/worker.py", line 741, in <module>', '  File "domain_dns/worker.py", line 736, in thread_run', '  File "python3.7/threading.py", line 1032, in join', '  File "python3.7/threading.py", line 1048, in _wait_for_tstate_lock']
2018-12-24 15:24:15,877 - ERROR - Sentry responded with an API error: APIError(Invalid api key)
2018-12-24 15:24:15,877 - ERROR - ['IndexError: pop from empty list', '  File "domain_dns/worker.py", line 643, in on_work', '  File "domain_dns/worker.py", line 541, in get_keyword']
2018-12-24 15:24:15,889 - ERROR - ["InternalError: (pymysql.err.InternalError) (1046, 'No database selected') [SQL: 'SELECT\\n                       record_pk,\\n                       `domain`\\n                       FROM\\n                       bulletin_search_domain_list\\n                       WHERE\\n                           status=0 \\n                       limit 50\\n                       for update'] (Background on this error at: http://sqlalche.me/e/2j85)", '  File "domain_dns/worker.py", line 504, in select_data', '  File "sqlalchemy/orm/session.py", line 1176, in execute', '  File "sqlalchemy/engine/base.py", line 948, in execute', '  File "sqlalchemy/sql/elements.py", line 269, in _execute_on_connection', '  File "sqlalchemy/engine/base.py", line 1060, in _execute_clauseelement', '  File "sqlalchemy/engine/base.py", line 1200, in _execute_context', '  File "sqlalchemy/engine/base.py", line 1413, in _handle_dbapi_exception', '  File "sqlalchemy/util/compat.py", line 265, in raise_from_cause', '  File "sqlalchemy/util/compat.py", line 248, in reraise', '  File "sqlalchemy/engine/base.py", line 1193, in _execute_context', '  File "sqlalchemy/engine/default.py", line 509, in do_execute', '  File "pymysql/cursors.py", line 170, in execute', '  File "pymysql/cursors.py", line 328, in _query', '  File "pymysql/connections.py", line 516, in query', '  File "pymysql/connections.py", line 727, in _read_query_result', '  File "pymysql/connections.py", line 1066, in read', '  File "pymysql/connections.py", line 683, in _read_packet', '  File "pymysql/protocol.py", line 220, in check_error', '  File "pymysql/err.py", line 109, in raise_mysql_exception']
2018-12-24 15:24:25,992 - ERROR - Sentry responded with an API error: APIError(Invalid api key)
2018-12-24 15:24:25,992 - ERROR - ['IndexError: pop from empty list', '  File "domain_dns/worker.py", line 643, in on_work', '  File "domain_dns/worker.py", line 541, in get_keyword']
2018-12-24 15:24:26,034 - ERROR - ["InternalError: (pymysql.err.InternalError) (1046, 'No database selected') [SQL: 'SELECT\\n                       record_pk,\\n                       `domain`\\n                       FROM\\n                       bulletin_search_domain_list\\n                       WHERE\\n                           status=0 \\n                       limit 50\\n                       for update'] (Background on this error at: http://sqlalche.me/e/2j85)", '  File "domain_dns/worker.py", line 504, in select_data', '  File "sqlalchemy/orm/session.py", line 1176, in execute', '  File "sqlalchemy/engine/base.py", line 948, in execute', '  File "sqlalchemy/sql/elements.py", line 269, in _execute_on_connection', '  File "sqlalchemy/engine/base.py", line 1060, in _execute_clauseelement', '  File "sqlalchemy/engine/base.py", line 1200, in _execute_context', '  File "sqlalchemy/engine/base.py", line 1413, in _handle_dbapi_exception', '  File "sqlalchemy/util/compat.py", line 265, in raise_from_cause', '  File "sqlalchemy/util/compat.py", line 248, in reraise', '  File "sqlalchemy/engine/base.py", line 1193, in _execute_context', '  File "sqlalchemy/engine/default.py", line 509, in do_execute', '  File "pymysql/cursors.py", line 170, in execute', '  File "pymysql/cursors.py", line 328, in _query', '  File "pymysql/connections.py", line 516, in query', '  File "pymysql/connections.py", line 727, in _read_query_result', '  File "pymysql/connections.py", line 1066, in read', '  File "pymysql/connections.py", line 683, in _read_packet', '  File "pymysql/protocol.py", line 220, in check_error', '  File "pymysql/err.py", line 109, in raise_mysql_exception']
2018-12-24 15:24:36,039 - ERROR - ['IndexError: pop from empty list', '  File "domain_dns/worker.py", line 643, in on_work', '  File "domain_dns/worker.py", line 541, in get_keyword']
2018-12-24 15:24:36,193 - ERROR - ["InternalError: (pymysql.err.InternalError) (1046, 'No database selected') [SQL: 'SELECT\\n                       record_pk,\\n                       `domain`\\n                       FROM\\n                       bulletin_search_domain_list\\n                       WHERE\\n                           status=0 \\n                       limit 50\\n                       for update'] (Background on this error at: http://sqlalche.me/e/2j85)", '  File "domain_dns/worker.py", line 504, in select_data', '  File "sqlalchemy/orm/session.py", line 1176, in execute', '  File "sqlalchemy/engine/base.py", line 948, in execute', '  File "sqlalchemy/sql/elements.py", line 269, in _execute_on_connection', '  File "sqlalchemy/engine/base.py", line 1060, in _execute_clauseelement', '  File "sqlalchemy/engine/base.py", line 1200, in _execute_context', '  File "sqlalchemy/engine/base.py", line 1413, in _handle_dbapi_exception', '  File "sqlalchemy/util/compat.py", line 265, in raise_from_cause', '  File "sqlalchemy/util/compat.py", line 248, in reraise', '  File "sqlalchemy/engine/base.py", line 1193, in _execute_context', '  File "sqlalchemy/engine/default.py", line 509, in do_execute', '  File "pymysql/cursors.py", line 170, in execute', '  File "pymysql/cursors.py", line 328, in _query', '  File "pymysql/connections.py", line 516, in query', '  File "pymysql/connections.py", line 727, in _read_query_result', '  File "pymysql/connections.py", line 1066, in read', '  File "pymysql/connections.py", line 683, in _read_packet', '  File "pymysql/protocol.py", line 220, in check_error', '  File "pymysql/err.py", line 109, in raise_mysql_exception']
2018-12-24 15:24:46,329 - ERROR - Sentry responded with an API error: APIError(Invalid api key)
2018-12-24 15:24:46,330 - ERROR - ['IndexError: pop from empty list', '  File "domain_dns/worker.py", line 643, in on_work', '  File "domain_dns/worker.py", line 541, in get_keyword']
2018-12-24 15:24:46,357 - ERROR - ["InternalError: (pymysql.err.InternalError) (1046, 'No database selected') [SQL: 'SELECT\\n                       record_pk,\\n                       `domain`\\n                       FROM\\n                       bulletin_search_domain_list\\n                       WHERE\\n                           status=0 \\n                       limit 50\\n                       for update'] (Background on this error at: http://sqlalche.me/e/2j85)", '  File "domain_dns/worker.py", line 504, in select_data', '  File "sqlalchemy/orm/session.py", line 1176, in execute', '  File "sqlalchemy/engine/base.py", line 948, in execute', '  File "sqlalchemy/sql/elements.py", line 269, in _execute_on_connection', '  File "sqlalchemy/engine/base.py", line 1060, in _execute_clauseelement', '  File "sqlalchemy/engine/base.py", line 1200, in _execute_context', '  File "sqlalchemy/engine/base.py", line 1413, in _handle_dbapi_exception', '  File "sqlalchemy/util/compat.py", line 265, in raise_from_cause', '  File "sqlalchemy/util/compat.py", line 248, in reraise', '  File "sqlalchemy/engine/base.py", line 1193, in _execute_context', '  File "sqlalchemy/engine/default.py", line 509, in do_execute', '  File "pymysql/cursors.py", line 170, in execute', '  File "pymysql/cursors.py", line 328, in _query', '  File "pymysql/connections.py", line 516, in query', '  File "pymysql/connections.py", line 727, in _read_query_result', '  File "pymysql/connections.py", line 1066, in read', '  File "pymysql/connections.py", line 683, in _read_packet', '  File "pymysql/protocol.py", line 220, in check_error', '  File "pymysql/err.py", line 109, in raise_mysql_exception']
2018-12-24 15:27:28,607 - ERROR - dictionary changed size during iteration
Traceback (most recent call last):
  File "/anaconda3/lib/python3.7/site-packages/raven/utils/serializer/manager.py", line 69, in transform
    return serializer.serialize(value, **kwargs)
  File "/anaconda3/lib/python3.7/site-packages/raven/utils/serializer/base.py", line 120, in serialize
    iteritems(value)))
  File "/anaconda3/lib/python3.7/site-packages/raven/utils/serializer/base.py", line 117, in <genexpr>
    (self.make_key(self.recurse(k, **kwargs)), self.recurse(v, **kwargs))
RuntimeError: dictionary changed size during iteration
2018-12-24 15:27:28,790 - ERROR - Sentry responded with an API error: APIError(Invalid api key)
2018-12-24 15:27:28,790 - ERROR - ['KeyboardInterrupt', '  File "pydev/pydevd.py", line 1591, in <module>', '  File "pydev/pydevd.py", line 1018, in run', '  File "_pydev_imps/_pydev_execfile.py", line 18, in execfile', '  File "domain_dns/worker.py", line 741, in <module>', '  File "domain_dns/worker.py", line 736, in thread_run', '  File "python3.7/threading.py", line 1032, in join', '  File "python3.7/threading.py", line 1048, in _wait_for_tstate_lock']
2018-12-24 15:27:52,656 - ERROR - dictionary changed size during iteration
Traceback (most recent call last):
  File "/anaconda3/lib/python3.7/site-packages/raven/utils/serializer/manager.py", line 69, in transform
    return serializer.serialize(value, **kwargs)
  File "/anaconda3/lib/python3.7/site-packages/raven/utils/serializer/base.py", line 120, in serialize
    iteritems(value)))
  File "/anaconda3/lib/python3.7/site-packages/raven/utils/serializer/base.py", line 117, in <genexpr>
    (self.make_key(self.recurse(k, **kwargs)), self.recurse(v, **kwargs))
RuntimeError: dictionary changed size during iteration
2018-12-24 15:27:52,836 - ERROR - Sentry responded with an API error: APIError(Invalid api key)
2018-12-24 15:27:52,837 - ERROR - ['KeyboardInterrupt', '  File "pydev/pydevd.py", line 1591, in <module>', '  File "pydev/pydevd.py", line 1018, in run', '  File "_pydev_imps/_pydev_execfile.py", line 18, in execfile', '  File "domain_dns/worker.py", line 741, in <module>', '  File "domain_dns/worker.py", line 736, in thread_run', '  File "python3.7/threading.py", line 1032, in join', '  File "python3.7/threading.py", line 1048, in _wait_for_tstate_lock']
